<?xml version="1.0" encoding="utf-8"?>
<robot xmlns:xacro="http://www.ros.org/wiki/xacro" name="base_rail1">
    <xacro:macro name="base1" params="parent *origin name:=base base_joint_type:=prismatic">


        <xacro:macro name="rail1_default_inertial">
            <inertial>
                    <mass value="0.024744" />
                    <inertia ixx="0.000017" ixy="0.0" ixz="0.0"
                            iyy="0.000016" iyz="0.0"
                            izz="0.000028" />
            </inertial>
        </xacro:macro>

        <link
            name="${name}_link">
            <visual>
            <origin
                xyz="0 0 0"
                rpy="0 0 0" />
            <geometry>
                <mesh
                filename="package://snake_robot1/meshes/base_link.STL" />
            </geometry>
            <material
                name="">
                <color
                rgba="0.75294 0.75294 0.75294 1" />
            </material>
            </visual>
            <collision>
            <origin
                xyz="0 0 0"
                rpy="0 0 0" />
            <geometry>
                <mesh
                filename="package://snake_robot1/meshes/base_link.STL" />
            </geometry>
            </collision>
        </link>
        <joint
        name="${name}_joint"
        type="${base_joint_type}">
        <xacro:insert_block name="origin" />
        <parent
            link="${parent}" />
        <child
            link="${name}_link" />
        <axis
            xyz="0 0 1" />
        <limit
        lower="-0.5"
        upper="0.5"
        effort="0"
        velocity="0" />
        </joint>
    </xacro:macro>

    <xacro:macro name="rail1" params="parent *origin name:=rail">
        <link
        name="${name}_link1">
        <xacro:rail1_default_inertial/>
        <visual>
        <origin
            xyz="0 0 0"
            rpy="0 0 0" />
        <geometry>
            <mesh
            filename="package://snake_robot1/meshes/link1.STL" />
        </geometry>
        <material
            name="">
            <color
            rgba="0.89804 0.91765 0.92941 1" />
        </material>
        </visual>
        <collision>
        <origin
            xyz="0 0 0"
            rpy="0 0 0" />
        <geometry>
            <mesh
            filename="package://snake_robot1/meshes/link1.STL" />
        </geometry>
        </collision>
    </link>
    <joint
        name="${name}_joint1"
        type="revolute">
        <xacro:insert_block name="origin" />
        <parent
        link="${parent}" />
        <child
        link="${name}_link1" />
        <axis
        xyz="-1 0 0" />
        <limit
        lower="-0.17"
        upper="0.17"
        effort="0"
        velocity="0" />
    </joint>
    <link
        name="${name}_link2">
        <xacro:rail1_default_inertial/>
        <visual>
        <origin
            xyz="0 0 0"
            rpy="0 0 0" />
        <geometry>
            <mesh
            filename="package://snake_robot1/meshes/link2.STL" />
        </geometry>
        <material
            name="">
            <color
            rgba="0.89804 0.91765 0.92941 1" />
        </material>
        </visual>
        <collision>
        <origin
            xyz="0 0 0"
            rpy="0 0 0" />
        <geometry>
            <mesh
            filename="package://snake_robot1/meshes/link2.STL" />
        </geometry>
        </collision>
    </link>
    <joint
        name="${name}_joint2"
        type="revolute">
        <origin
        xyz="0 0 0.021"
        rpy="0 0 0" />
        <parent
        link="${name}_link1" />
        <child
        link="${name}_link2" />
        <axis
        xyz="0 -1 0" />
        <limit
        lower="-0.17"
        upper="0.17"
        effort="0"
        velocity="0" />
    </joint>
    <link
        name="${name}_link3">
        <xacro:rail1_default_inertial/>
        <visual>
        <origin
            xyz="0 0 0"
            rpy="0 0 0" />
        <geometry>
            <mesh
            filename="package://snake_robot1/meshes/link3.STL" />
        </geometry>
        <material
            name="">
            <color
            rgba="0.89804 0.91765 0.92941 1" />
        </material>
        </visual>
        <collision>
        <origin
            xyz="0 0 0"
            rpy="0 0 0" />
        <geometry>
            <mesh
            filename="package://snake_robot1/meshes/link3.STL" />
        </geometry>
        </collision>
    </link>
    <joint
        name="${name}_joint3"
        type="revolute">
        <origin
        xyz="0 0 0.021"
        rpy="0 0 0" />
        <parent
        link="${name}_link2" />
        <child
        link="${name}_link3" />
        <axis
        xyz="1 0 0" />
        <limit
        lower="-0.17"
        upper="0.17"
        effort="0"
        velocity="0" />
    </joint>
    <link
        name="${name}_link4">
        <xacro:rail1_default_inertial/>
        <visual>
        <origin
            xyz="0 0 0"
            rpy="0 0 0" />
        <geometry>
            <mesh
            filename="package://snake_robot1/meshes/link4.STL" />
        </geometry>
        <material
            name="">
            <color
            rgba="0.89804 0.91765 0.92941 1" />
        </material>
        </visual>
        <collision>
        <origin
            xyz="0 0 0"
            rpy="0 0 0" />
        <geometry>
            <mesh
            filename="package://snake_robot1/meshes/link4.STL" />
        </geometry>
        </collision>
    </link>
    <joint
        name="${name}_joint4"
        type="revolute">
        <origin
        xyz="0 0 0.021"
        rpy="0 0 0" />
        <parent
        link="${name}_link3" />
        <child
        link="${name}_link4" />
        <axis
        xyz="0 -1 0" />
        <limit
        lower="-0.17"
        upper="0.17"
        effort="0"
        velocity="0" />
    </joint>
    <link
        name="${name}_link5">
        <xacro:rail1_default_inertial/>
        <visual>
        <origin
            xyz="0 0 0"
            rpy="0 0 0" />
        <geometry>
            <mesh
            filename="package://snake_robot1/meshes/link5.STL" />
        </geometry>
        <material
            name="">
            <color
            rgba="0.89804 0.91765 0.92941 1" />
        </material>
        </visual>
        <collision>
        <origin
            xyz="0 0 0"
            rpy="0 0 0" />
        <geometry>
            <mesh
            filename="package://snake_robot1/meshes/link5.STL" />
        </geometry>
        </collision>
    </link>
    <joint
        name="${name}_joint5"
        type="revolute">
        <origin
        xyz="0 0 0.021"
        rpy="0 0 0" />
        <parent
        link="${name}_link4" />
        <child
        link="${name}_link5" />
        <axis
        xyz="1 0 0" />
        <limit
        lower="-0.17"
        upper="0.17"
        effort="0"
        velocity="0" />
        </joint>
    </xacro:macro>
</robot>
